Workbook
Name SegmentaciónDeDatos_C_de_PROCESO: #N/A
Name SegmentaciónDeDatos_TIPO_DE_VENTA: #N/A

Sheet Dashboard
I20: CALIFICACIÓN POR CENTRO DE PROCESO SEGÚN INSUMOS
I21: Estado | J21: Calificación | L21: 1 | M21: 2 | N21: 3 | O21: 4 | P21: 5
I22: =Tablas!X10 -> Guadalajara | J22: 4.5705409 | L22: =IF(L$21<=$J22,1,IF(ROUNDUP($J22,0)=L$21,MOD($J22,1),0)) -> 1 | M22: =IF(M$21<=$J22,1,IF(ROUNDUP($J22,0)=M$21,MOD($J22,1),0)) -> 1 | N22: =IF(N$21<=$J22,1,IF(ROUNDUP($J22,0)=N$21,MOD($J22,1),0)) -> 1 | O22: =IF(O$21<=$J22,1,IF(ROUNDUP($J22,0)=O$21,MOD($J22,1),0)) -> 1 | P22: =IF(P$21<=$J22,1,IF(ROUNDUP($J22,0)=P$21,MOD($J22,1),0)) -> 0.57054087
I23: =Tablas!X8 -> Monterrey | J23: 4.4638342 | L23: =IF(L$21<=$J23,1,IF(ROUNDUP($J23,0)=L$21,MOD($J23,1),0)) -> 1 | M23: =IF(M$21<=$J23,1,IF(ROUNDUP($J23,0)=M$21,MOD($J23,1),0)) -> 1 | N23: =IF(N$21<=$J23,1,IF(ROUNDUP($J23,0)=N$21,MOD($J23,1),0)) -> 1 | O23: =IF(O$21<=$J23,1,IF(ROUNDUP($J23,0)=O$21,MOD($J23,1),0)) -> 1 | P23: =IF(P$21<=$J23,1,IF(ROUNDUP($J23,0)=P$21,MOD($J23,1),0)) -> 0.46383423
I24: =Tablas!X6 -> Mérida | J24: 4.3294976 | L24: =IF(L$21<=$J24,1,IF(ROUNDUP($J24,0)=L$21,MOD($J24,1),0)) -> 1 | M24: =IF(M$21<=$J24,1,IF(ROUNDUP($J24,0)=M$21,MOD($J24,1),0)) -> 1 | N24: =IF(N$21<=$J24,1,IF(ROUNDUP($J24,0)=N$21,MOD($J24,1),0)) -> 1 | O24: =IF(O$21<=$J24,1,IF(ROUNDUP($J24,0)=O$21,MOD($J24,1),0)) -> 1 | P24: =IF(P$21<=$J24,1,IF(ROUNDUP($J24,0)=P$21,MOD($J24,1),0)) -> 0.3294976
I25: =Tablas!X7 -> Coatzacoalcos | J25: 4.2777713 | L25: =IF(L$21<=$J25,1,IF(ROUNDUP($J25,0)=L$21,MOD($J25,1),0)) -> 1 | M25: =IF(M$21<=$J25,1,IF(ROUNDUP($J25,0)=M$21,MOD($J25,1),0)) -> 1 | N25: =IF(N$21<=$J25,1,IF(ROUNDUP($J25,0)=N$21,MOD($J25,1),0)) -> 1 | O25: =IF(O$21<=$J25,1,IF(ROUNDUP($J25,0)=O$21,MOD($J25,1),0)) -> 1 | P25: =IF(P$21<=$J25,1,IF(ROUNDUP($J25,0)=P$21,MOD($J25,1),0)) -> 0.27777129
I26: =Tablas!X9 -> Cancún | J26: 3.8499972 | L26: =IF(L$21<=$J26,1,IF(ROUNDUP($J26,0)=L$21,MOD($J26,1),0)) -> 1 | M26: =IF(M$21<=$J26,1,IF(ROUNDUP($J26,0)=M$21,MOD($J26,1),0)) -> 1 | N26: =IF(N$21<=$J26,1,IF(ROUNDUP($J26,0)=N$21,MOD($J26,1),0)) -> 1 | O26: =IF(O$21<=$J26,1,IF(ROUNDUP($J26,0)=O$21,MOD($J26,1),0)) -> 0.84999717 | P26: =IF(P$21<=$J26,1,IF(ROUNDUP($J26,0)=P$21,MOD($J26,1),0)) -> 0
I27: =Tablas!X5 -> Acapulco | J27: 3.6617159 | L27: =IF(L$21<=$J27,1,IF(ROUNDUP($J27,0)=L$21,MOD($J27,1),0)) -> 1 | M27: =IF(M$21<=$J27,1,IF(ROUNDUP($J27,0)=M$21,MOD($J27,1),0)) -> 1 | N27: =IF(N$21<=$J27,1,IF(ROUNDUP($J27,0)=N$21,MOD($J27,1),0)) -> 1 | O27: =IF(O$21<=$J27,1,IF(ROUNDUP($J27,0)=O$21,MOD($J27,1),0)) -> 0.66171592 | P27: =IF(P$21<=$J27,1,IF(ROUNDUP($J27,0)=P$21,MOD($J27,1),0)) -> 0
I28: =Tablas!X4 -> Campeche | J28: 3.5679921 | L28: =IF(L$21<=$J28,1,IF(ROUNDUP($J28,0)=L$21,MOD($J28,1),0)) -> 1 | M28: =IF(M$21<=$J28,1,IF(ROUNDUP($J28,0)=M$21,MOD($J28,1),0)) -> 1 | N28: =IF(N$21<=$J28,1,IF(ROUNDUP($J28,0)=N$21,MOD($J28,1),0)) -> 1 | O28: =IF(O$21<=$J28,1,IF(ROUNDUP($J28,0)=O$21,MOD($J28,1),0)) -> 0.56799214 | P28: =IF(P$21<=$J28,1,IF(ROUNDUP($J28,0)=P$21,MOD($J28,1),0)) -> 0
I29: =Tablas!X3 -> Oaxaca | J29: 2.2792733 | L29: =IF(L$21<=$J29,1,IF(ROUNDUP($J29,0)=L$21,MOD($J29,1),0)) -> 1 | M29: =IF(M$21<=$J29,1,IF(ROUNDUP($J29,0)=M$21,MOD($J29,1),0)) -> 1 | N29: =IF(N$21<=$J29,1,IF(ROUNDUP($J29,0)=N$21,MOD($J29,1),0)) -> 0.27927329 | O29: =IF(O$21<=$J29,1,IF(ROUNDUP($J29,0)=O$21,MOD($J29,1),0)) -> 0 | P29: =IF(P$21<=$J29,1,IF(ROUNDUP($J29,0)=P$21,MOD($J29,1),0)) -> 0
I30: =Tablas!X11 -> CDMX | J30: 0 | L30: =IF(L$21<=$J30,1,IF(ROUNDUP($J30,0)=L$21,MOD($J30,1),0)) -> 0 | M30: =IF(M$21<=$J30,1,IF(ROUNDUP($J30,0)=M$21,MOD($J30,1),0)) -> 0 | N30: =IF(N$21<=$J30,1,IF(ROUNDUP($J30,0)=N$21,MOD($J30,1),0)) -> 0 | O30: =IF(O$21<=$J30,1,IF(ROUNDUP($J30,0)=O$21,MOD($J30,1),0)) -> 0 | P30: =IF(P$21<=$J30,1,IF(ROUNDUP($J30,0)=P$21,MOD($J30,1),0)) -> 0

Sheet Tablas
O1: Centro de proceso | S1: Nombre corto | T1: Nombre | U1: Cantidad | V1: Cantidad 3 | X1: Isumos
A2: Utilidad | B2: =IF(C8<>"","Otro",L8) -> Otro | C2: =VLOOKUP(B2,$A$49:$B$58,2,0) -> 60839660 | O2: CDMX | P2: =IFERROR(100%-P15*100%/Q15,"- %") -> -0.39774143 | S2: =IFERROR(VLOOKUP(O2,$O$13:$P$22,1,0),"") -> CDMX | T2: =IFERROR(VLOOKUP(S2,$S$15:$T$24,2,0),"") -> #VALUE! | U2: =IFERROR(VLOOKUP(S2,$O$13:$P$13,2,0),"") | V2: =P2 -> -0.39774143 | X2: Estado | Y2: Calificación
A3: Reantabilidad | B3: =IF(C8<>"","Otro",L8) -> Otro | C3: =VLOOKUP(B3,$A$36:$B$45,2,0) -> 0.2201708 | O3: CAM | P3: =IFERROR(100%-P16*100%/Q16,"- %") -> 0.28429494 | S3: =IFERROR(VLOOKUP(O3,$O$13:$P$22,1,0),"") -> CAM | T3: =IFERROR(VLOOKUP(S3,$S$15:$T$24,2,0),"") -> #VALUE! | U3: =IFERROR(VLOOKUP(S3,$O$13:$P$13,2,0),"") | V3: =P3 -> 0.28429494 | X3: Oaxaca | Y3: 50
O4: ACA | P4: =IFERROR(100%-P17*100%/Q17,"- %") -> 0.090708182 | S4: =IFERROR(VLOOKUP(O4,$O$13:$P$22,1,0),"") -> ACA | T4: =IFERROR(VLOOKUP(S4,$S$15:$T$24,2,0),"") -> #VALUE! | U4: =IFERROR(VLOOKUP(S4,$O$13:$P$13,2,0),"") | V4: =P4 -> 0.090708182 | X4: Campeche | Y4: 30
O5: GDL | P5: =IFERROR(100%-P18*100%/Q18,"- %") -> 0.40025047 | S5: =IFERROR(VLOOKUP(O5,$O$13:$P$22,1,0),"") -> GDL | T5: =IFERROR(VLOOKUP(S5,$S$15:$T$24,2,0),"") -> #VALUE! | U5: =IFERROR(VLOOKUP(S5,$O$13:$P$13,2,0),"") | V5: =P5 -> 0.40025047 | X5: Acapulco | Y5: 10
O6: MTY | P6: =IFERROR(100%-P19*100%/Q19,"- %") -> 0.20336897 | S6: =IFERROR(VLOOKUP(O6,$O$13:$P$22,1,0),"") -> MTY | T6: =IFERROR(VLOOKUP(S6,$S$15:$T$24,2,0),"") -> #VALUE! | U6: =IFERROR(VLOOKUP(S6,$O$13:$P$13,2,0),"") | V6: =P6 -> 0.20336897 | X6: Mérida | Y6: 15
A7: Rentabilidad | B7: C P | O7: OAX | P7: =IFERROR(100%-P20*100%/Q20,"- %") -> -0.12639978 | S7: =IFERROR(VLOOKUP(O7,$O$13:$P$22,1,0),"") -> OAX | T7: =IFERROR(VLOOKUP(S7,$S$15:$T$24,2,0),"") -> #VALUE! | U7: =IFERROR(VLOOKUP(S7,$O$13:$P$13,2,0),"") | V7: =P7 -> -0.12639978 | X7: Coatzacoalcos | Y7: 35
A8: Mes | B8: ACA | C8: CAM | D8: CUN | E8: CDMX | F8: GDL | G8: MID | H8: MTY | I8: OAX | J8: Qtza | K8: Otro | L8: =IF(C8<>"",K8,B8) -> Otro | O8: CUN | P8: =IFERROR(100%-P21*100%/Q21,"- %") -> -0.58678482 | S8: =IFERROR(VLOOKUP(O8,$O$13:$P$22,1,0),"") -> CUN | T8: =IFERROR(VLOOKUP(S8,$S$15:$T$24,2,0),"") -> #VALUE! | U8: =IFERROR(VLOOKUP(S8,$O$13:$P$13,2,0),"") | V8: =P8 -> -0.58678482 | X8: Monterrey | Y8: 65
A9: ENERO | B9: 0.36 | C9: 0.24 | D9: 0.42 | E9: 0.62752925 | F9: 0.48 | G9: 0.61 | H9: 0.43 | I9: 0.50574517 | J9: 0.58 | K9: 0.64101215 | L9: =IF(C9<>"",K9,B9) -> 0.64101215 | O9: Qtza | P9: =IFERROR(100%-P22*100%/Q22,"- %") -> 0.042422898 | S9: =IFERROR(VLOOKUP(O9,$O$13:$P$22,1,0),"") -> Qtza | T9: =IFERROR(VLOOKUP(S9,$S$15:$T$24,2,0),"") -> #VALUE! | U9: =IFERROR(VLOOKUP(S9,$O$13:$P$13,2,0),"") | V9: =P9 -> 0.042422898 | X9: Cancún | Y9: 84
A10: FEBRERO | B10: 0.38877758 | C10: 0.15124161 | D10: 0.32010011 | E10: 0.064273559 | F10: 0.58381909 | G10: 0.61948939 | H10: 0.34074443 | I10: -0.396428 | J10: 0.43100859 | K10: -0.11503683 | L10: =IF(C10<>"",K10,B10) -> -0.11503683 | O10: MID | P10: =IFERROR(100%-P23*100%/Q23,"- %") -> 0.22363589 | S10: MID | T10: Mérida | U10: =IFERROR(VLOOKUP(S10,$O$13:$P$13,2,0),"") | V10: =P10 -> 0.22363589 | X10: Guadalajara | Y10: 85
A11: MARZO | B11: 0.35011666 | C11: 0.057439818 | D11: 0.11381325 | E11: 0.07764953 | F11: 0.17617376 | G11: 0.40944863 | H11: 0.30646411 | I11: -0.35674668 | J11: 0.38385351 | K11: -0.26226021 | L11: =IF(C11<>"",K11,B11) -> -0.26226021 | O11: Otro | P11: =IFERROR(100%-P24*100%/Q24,"- %") -> -0.17787614 | S11: Otro | T11: México | U11: =IFERROR(VLOOKUP(S11,$O$13:$P$13,2,0),"") -> -0.17787614 | V11: =P11 -> -0.17787614 | X11: CDMX | Y11: 90
A12: ABRIL | B12: 0.33977459 | C12: 0.51082036 | D12: -0.088074018 | E12: -0.44824225 | F12: 0.20249035 | G12: 0.40413147 | H12: 0.38769939 | I12: -0.1237311 | J12: 0.13350062 | K12: -0.36375548 | L12: =IF(C12<>"",K12,B12) -> -0.36375548 | O12: Porcentaje de crecimiento anual
A13: MAYO | B13: -0.60957026 | C13: -0.63131379 | D13: -2.0175557 | E13: -0.20655204 | F13: -0.0053307884 | G13: -0.41564763 | H13: -0.06550531 | I13: -0.98014423 | J13: -0.052783459 | K13: 0.21420985 | L13: =IF(C13<>"",K13,B13) -> 0.21420985 | O13: =L8 -> Otro | P13: =VLOOKUP(O13,O2:P11,2,0) -> -0.17787614
O14: CP | P14: 2021 | Q14: 2022
A15: AÑO | B15: 2022 | O15: CDMX | P15: =SUM(U36:Y36) -> 1.9484501e+08 | Q15: =SUM(AG36:AK36) -> 1.3939989e+08 | S15: CDMX | T15: #VALUE!
O16: CAM | P16: =SUM(U37:Y37) -> 3699880.3 | Q16: =SUM(AG37:AK37) -> 5169560.1 | S16: CAM | T16: #VALUE!
A17: Utilidad | B17: Mes | O17: ACA | P17: =SUM(U38:Y38) -> 6178556.7 | Q17: =SUM(AG38:AK38) -> 6794910.7 | S17: ACA | T17: #VALUE!
A18: C P | B18: ENERO | C18: FEBRERO | D18: MARZO | E18: ABRIL | F18: MAYO | O18: GDL | P18: =SUM(U39:Y39) -> 9075563.7 | Q18: =SUM(AG39:AK39) -> 15132256 | S18: GDL | T18: #VALUE!
A19: ACA | B19: 2181525.4 | C19: 1863307.5 | D19: 1203637.7 | E19: 1062832.7 | F19: 483607.48 | O19: MTY | P19: =SUM(U40:Y40) -> 18902949 | Q19: =SUM(AG40:AK40) -> 23728613 | S19: MTY | T19: #VALUE!
A20: CAM | B20: 1562010.4 | C20: 1017245.7 | D20: 794246.95 | E20: 1343869.4 | F20: 452187.71 | O20: OAX | P20: =SUM(U41:Y41) -> 2789748.7 | Q20: =SUM(AG41:AK41) -> 2476695 | S20: OAX | T20: #VALUE!
A21: CUN | B21: 9724529.6 | C21: 7891595.9 | D21: 4726182.7 | E21: 3414983.9 | F21: 896398.12 | O21: CUN | P21: =SUM(U42:Y42) -> 42293671 | Q21: =SUM(AG42:AK42) -> 26653690 | S21: CUN | T21: #VALUE!
A22: Qtza | B22: 2508115.7 | C22: 2028083.8 | D22: 1711111.3 | E22: 1667247.1 | F22: 1025793.8 | O22: Qtza | P22: =SUM(U43:Y43) -> 8561076 | Q22: =SUM(AG43:AK43) -> 8940351.6 | S22: Qtza | T22: #VALUE!
A23: CDMX | B23: 51801996 | C23: 27174015 | D23: 24774697 | E23: 20493928 | F23: 15155258 | O23: MID | P23: =SUM(U44:Y44) -> 17307160 | Q23: 22292581 | S23: MID | T23: #VALUE!
A24: GDL | B24: 6585878.7 | C24: 3828324.8 | D24: 2270751 | E24: 1430125.7 | F24: 1017176.2 | O24: Otro | P24: =SUM(U45:Y45) -> 3.0365361e+08 | Q24: =SUM(AG45:AK45) -> 2.5779757e+08 | S24: Otro | T24: #VALUE!
A25: MID | B25: 9391953.6 | C25: 7019082.2 | D25: 3319857.2 | E25: 2561688.1 | F25: 1160808.5
A26: MTY | B26: 10453007 | C26: 4324806.5 | D26: 3139176.9 | E26: 3037284.3 | F26: 2774338.4 | O26: Venta total
A27: OAX | B27: 515532.91 | C27: 514785.95 | D27: 546816.53 | E27: 617853.64 | F27: 281706 | O27: =L8 -> Otro | P27: =SUM(P29:P40) -> 7.0738915e+08 | Q27: =SUM(Q29:Q33) -> 2.5779757e+08
A28: Otro | B28: 94724549 | C28: 55661248 | D28: 42486477 | E28: 35678026 | F28: 29247274 | O28: Mes | P28: 2021 | Q28: 2022
O29: ENERO | P29: =VLOOKUP($O$27,$T$36:$AF$45,2,0) -> 79521841 | Q29: =VLOOKUP(O27,T36:AK45,14,0) -> 94724549
A30: =B8 -> ACA | B30: =VLOOKUP($A$30,$A$19:$M$29,2,0) -> 2181525.4 | C30: =VLOOKUP($A$30,$A$19:$M$29,3,0) -> 1863307.5 | D30: =VLOOKUP($A$30,$A$19:$M$29,4,0) -> 1203637.7 | E30: =VLOOKUP($A$30,$A$19:$M$29,5,0) -> 1062832.7 | F30: =VLOOKUP($A$30,$A$19:$M$29,6,0) -> 483607.48 | G30: =VLOOKUP($A$30,$A$19:$M$29,7,0) -> 0 | H30: =VLOOKUP($A$30,$A$19:$M$29,8,0) -> 0 | I30: =VLOOKUP($A$30,$A$19:$M$29,9,0) -> 0 | J30: =VLOOKUP($A$30,$A$19:$M$29,10,0) -> 0 | K30: =VLOOKUP($A$30,$A$19:$M$29,11,0) -> 0 | L30: =VLOOKUP($A$30,$A$19:$M$29,12,0) -> 0 | M30: =VLOOKUP($A$30,$A$19:$M$29,13,0) -> 0 | O30: FEBRERO | P30: =VLOOKUP($O$27,$T$36:$AF$45,3,0) -> 77047189 | Q30: =VLOOKUP(O27,T36:AK45,15,0) -> 55661248
O31: MARZO | P31: =VLOOKUP($O$27,$T$36:$AF$45,4,0) -> 51587914 | Q31: =VLOOKUP(O27,T36:AK45,16,0) -> 42486477 | T31: TIPO DE VENTA | U31: (Todas)
O32: ABRIL | P32: =VLOOKUP($O$27,$T$36:$AF$45,5,0) -> 55574998 | Q32: =VLOOKUP(O27,T36:AK45,17,0) -> 35678026
O33: MAYO | P33: =VLOOKUP($O$27,$T$36:$AF$45,6,0) -> 39921671 | Q33: =VLOOKUP(O27,T36:AK45,18,0) -> 29247274 | T33: Suma de CANTIDAD | U33: Tipo
A34: Rentabilidad | B34: 2022 | O34: JUNIO | P34: =VLOOKUP($O$27,$T$36:$AF$45,7,0) -> 46512450 | U34: 2021 | AG34: 2022
A35: Centro de Proceso | B35: Acumulado | D35: Acumulado a abril de 2022 | O35: JULIO | P35: =VLOOKUP($O$27,$T$36:$AF$45,8,0) -> 55562816 | T35: Mes | U35: ENERO | V35: FEBRERO | W35: MARZO | X35: ABRIL | Y35: MAYO | Z35: JUNIO | AA35: JULIO | AB35: AGOSTO | AC35: SEPTIEMBRE | AD35: OCTUBRE | AE35: NOVIEMBRE | AF35: DICIEMBRE | AG35: ENERO | AH35: FEBRERO | AI35: MARZO | AJ35: ABRIL | AK35: MAYO
A36: OAX | B36: 0.020661016 | D36: Utilidad | E36: 59446610 | O36: AGOSTO | P36: =VLOOKUP($O$27,$T$36:$AF$45,9,0) -> 77227045 | T36: CDMX | U36: 54001950 | V36: 49598673 | W36: 32473063 | X36: 33188502 | Y36: 25582820 | Z36: 27224676 | AA36: 33652943 | AB36: 45396042 | AC36: 31847415 | AD36: 27788628 | AE36: 26330812 | AF36: 29797776 | AG36: 51801996 | AH36: 27174015 | AI36: 24774697 | AJ36: 20493928 | AK36: 15155258
A37: CAM | B37: 0.51841155 | D37: Rentabilidad: | E37: 0.33721874 | O37: SEPTIEMBRE | P37: =VLOOKUP($O$27,$T$36:$AF$45,10,0) -> 52928219 | T37: CAM | U37: 582597.28 | V37: 756640.77 | W37: 833992.37 | X37: 1117497.4 | Y37: 409152.49 | Z37: 908388.88 | AA37: 837164.48 | AB37: 941174.94 | AC37: 973402.13 | AD37: 589207.74 | AE37: 605130.08 | AF37: 759831.09 | AG37: 1562010.4 | AH37: 1017245.7 | AI37: 794246.95 | AJ37: 1343869.4 | AK37: 452187.71
A38: ACA | B38: 0.58813859 | O38: OCTUBRE | P38: =VLOOKUP($O$27,$T$36:$AF$45,11,0) -> 47270020 | T38: ACA | U38: 1068977 | V38: 1325668.2 | W38: 1259503.2 | X38: 1632366.1 | Y38: 892042.15 | Z38: 1267556.6 | AA38: 1537607.1 | AB38: 1973349.7 | AC38: 1060542.9 | AD38: 1253440.6 | AE38: 1357952.9 | AF38: 1818173.9 | AG38: 2181525.4 | AH38: 1863307.5 | AI38: 1203637.7 | AJ38: 1062832.7 | AK38: 483607.48
A39: MID | B39: 0.74639151 | O39: NOVIEMBRE | P39: =VLOOKUP($O$27,$T$36:$AF$45,12,0) -> 51178223 | T39: GDL | U39: 3022833.3 | V39: 2395045 | W39: 1275641.6 | X39: 1367285 | Y39: 1014758.7 | Z39: 962228.12 | AA39: 1602686.2 | AB39: 3198175.7 | AC39: 2365474.3 | AD39: 1685203.9 | AE39: 2300892.5 | AF39: 5404624.4 | AG39: 6585878.7 | AH39: 3828324.8 | AI39: 2270751 | AJ39: 1430125.7 | AK39: 1017176.2
A40: Qtza | B40: 0.42483932 | O40: DICIEMBRE | P40: =VLOOKUP($O$27,$T$36:$AF$45,13,0) -> 73056764 | T40: MTY | U40: 4951894.8 | V40: 4979725.5 | W40: 2794013.1 | X40: 3382593.3 | Y40: 2794722.3 | Z40: 3513042.6 | AA40: 4749480.8 | AB40: 8969326.9 | AC40: 5919142.2 | AD40: 3986355.6 | AE40: 3644992.6 | AF40: 4631116.9 | AG40: 10453007 | AH40: 4324806.5 | AI40: 3139176.9 | AJ40: 3037284.3 | AK40: 2774338.4
...

Sheet Datos
B1: VENTA TOTAL | I1: RENTABILIDAD | N1: UTLIDAD
B2: MES | C2: CANTIDAD | D2: AÑO | E2: TIPO DE VENTA | F2: C de PROCESO | G2: ESTADO | I2: MES | J2: CANTIDAD | K2: AÑO | L2: C de PROCESO | N2: MES | O2: CANTIDAD | P2: AÑO | Q2: C de PROCESO | T2: C de Proceso | U2: Estado
B3: ENERO | C3: 3132 | D3: 2021 | E3: Cliente 01 | F3: OAX | G3: =VLOOKUP(F3,$T$3:$U$11,2,0) -> Oaxaca | I3: ENERO | J3: 0.50574517 | K3: 2022 | L3: OAX | N3: ENERO | O3: 393485.1 | P3: 2021 | Q3: OAX | T3: ACA | U3: Guerrero
B4: FEBRERO | C4: 1566 | D4: 2021 | E4: Cliente 01 | F4: OAX | G4: =VLOOKUP(F4,$T$3:$U$11,2,0) -> Oaxaca | I4: FEBRERO | J4: -0.396428 | K4: 2022 | L4: OAX | N4: FEBRERO | O4: 4211.2506 | P4: 2021 | Q4: OAX | T4: CDMX | U4: CDMX
B5: MARZO | C5: 22504 | D5: 2021 | E5: Cliente 01 | F5: OAX | G5: =VLOOKUP(F5,$T$3:$U$11,2,0) -> Oaxaca | I5: MARZO | J5: -0.35674668 | K5: 2022 | L5: OAX | N5: MARZO | O5: 102405.34 | P5: 2021 | Q5: OAX | T5: CUN | U5: Quintana Roo
B6: ABRIL | C6: 51678 | D6: 2021 | E6: Cliente 01 | F6: OAX | G6: =VLOOKUP(F6,$T$3:$U$11,2,0) -> Oaxaca | I6: ABRIL | J6: -0.1237311 | K6: 2022 | L6: OAX | N6: ABRIL | O6: 94620.693 | P6: 2021 | Q6: OAX | T6: GDL | U6: Jalisco
B7: MAYO | C7: 19140 | D7: 2021 | E7: Cliente 01 | F7: OAX | G7: =VLOOKUP(F7,$T$3:$U$11,2,0) -> Oaxaca | I7: MAYO | J7: -0.98014423 | K7: 2022 | L7: OAX | N7: MAYO | O7: -273626.09 | P7: 2021 | Q7: OAX | T7: MID | U7: Yucatán
B8: JUNIO | C8: 11310 | D8: 2021 | E8: Cliente 01 | F8: OAX | G8: =VLOOKUP(F8,$T$3:$U$11,2,0) -> Oaxaca | I8: JUNIO | J8: - | K8: 2022 | L8: OAX | N8: JUNIO | O8: -354.81673 | P8: 2021 | Q8: OAX | T8: MTY | U8: Nuevo León
B9: JULIO | C9: 43500 | D9: 2021 | E9: Cliente 01 | F9: OAX | G9: =VLOOKUP(F9,$T$3:$U$11,2,0) -> Oaxaca | I9: JULIO | J9: - | K9: 2022 | L9: OAX | N9: JULIO | O9: -63500.716 | P9: 2021 | Q9: OAX | T9: OAX | U9: Oaxaca
B10: AGOSTO | C10: 46980 | D10: 2021 | E10: Cliente 01 | F10: OAX | G10: =VLOOKUP(F10,$T$3:$U$11,2,0) -> Oaxaca | I10: AGOSTO | J10: - | K10: 2022 | L10: OAX | N10: AGOSTO | O10: -275356.89 | P10: 2021 | Q10: OAX | T10: Otro | U10: México
B11: SEPTIEMBRE | C11: 33060 | D11: 2021 | E11: Cliente 01 | F11: OAX | G11: =VLOOKUP(F11,$T$3:$U$11,2,0) -> Oaxaca | I11: SEPTIEMBRE | J11: - | K11: 2022 | L11: OAX | N11: SEPTIEMBRE | O11: -139141.13 | P11: 2021 | Q11: OAX | T11: Qtza | U11: Veracruz
B12: OCTUBRE | C12: 8700 | D12: 2021 | E12: Cliente 01 | F12: OAX | G12: =VLOOKUP(F12,$T$3:$U$11,2,0) -> Oaxaca | I12: OCTUBRE | J12: - | K12: 2022 | L12: OAX | N12: OCTUBRE | O12: 148896.53 | P12: 2021 | Q12: OAX | T12: CAM | U12: Campeche
B13: NOVIEMBRE | C13: 9860 | D13: 2021 | E13: Cliente 01 | F13: OAX | G13: =VLOOKUP(F13,$T$3:$U$11,2,0) -> Oaxaca | I13: NOVIEMBRE | J13: - | K13: 2022 | L13: OAX | N13: NOVIEMBRE | O13: -31246.308 | P13: 2021 | Q13: OAX
B14: DICIEMBRE | C14: 2610 | D14: 2021 | E14: Cliente 01 | F14: OAX | G14: =VLOOKUP(F14,$T$3:$U$11,2,0) -> Oaxaca | I14: DICIEMBRE | J14: - | K14: 2022 | L14: OAX | N14: DICIEMBRE | O14: -372507.61 | P14: 2021 | Q14: OAX
B15: ENERO | C15: 48720 | D15: 2022 | E15: Cliente 01 | F15: OAX | G15: =VLOOKUP(F15,$T$3:$U$11,2,0) -> Oaxaca | I15: ENERO | J15: 0.24 | K15: 2022 | L15: CAM | N15: ENERO | O15: 521456.56 | P15: 2022 | Q15: OAX
B16: FEBRERO | C16: 9570 | D16: 2022 | E16: Cliente 01 | F16: OAX | G16: =VLOOKUP(F16,$T$3:$U$11,2,0) -> Oaxaca | I16: FEBRERO | J16: 0.15124161 | K16: 2022 | L16: CAM | N16: FEBRERO | O16: -204075.56 | P16: 2022 | Q16: OAX
B17: MARZO | C17: 2610 | D17: 2022 | E17: Cliente 01 | F17: OAX | G17: =VLOOKUP(F17,$T$3:$U$11,2,0) -> Oaxaca | I17: MARZO | J17: 0.057439818 | K17: 2022 | L17: CAM | N17: MARZO | O17: -192610.82 | P17: 2022 | Q17: OAX
B18: ABRIL | C18: 870 | D18: 2022 | E18: Cliente 01 | F18: OAX | G18: =VLOOKUP(F18,$T$3:$U$11,2,0) -> Oaxaca | I18: ABRIL | J18: 0.51082036 | K18: 2022 | L18: CAM | N18: ABRIL | O18: -69989.212 | P18: 2022 | Q18: OAX
B19: MAYO | C19: - | D19: 2022 | E19: Cliente 01 | F19: OAX | G19: =VLOOKUP(F19,$T$3:$U$11,2,0) -> Oaxaca | I19: MAYO | J19: -0.63131379 | K19: 2022 | L19: CAM | N19: MAYO | O19: -276112.51 | P19: 2022 | Q19: OAX
B20: ENERO | C20: 160769.04 | D20: 2021 | E20: Cliente 01 | F20: CAM | G20: =VLOOKUP(F20,$T$3:$U$12,2,0) -> Campeche | I20: JUNIO | J20: - | K20: 2022 | L20: CAM | N20: JUNIO | O20: 0 | P20: 2022 | Q20: OAX
B21: FEBRERO | C21: 173761.04 | D21: 2021 | E21: Cliente 01 | F21: CAM | G21: =VLOOKUP(F21,$T$3:$U$12,2,0) -> Campeche | I21: JULIO | J21: - | K21: 2022 | L21: CAM | N21: JULIO | O21: 0 | P21: 2022 | Q21: OAX
B22: MARZO | C22: 196504 | D22: 2021 | E22: Cliente 01 | F22: CAM | G22: =VLOOKUP(F22,$T$3:$U$12,2,0) -> Campeche | I22: AGOSTO | J22: - | K22: 2022 | L22: CAM | N22: AGOSTO | O22: 0 | P22: 2022 | Q22: OAX
B23: ABRIL | C23: 376304 | D23: 2021 | E23: Cliente 01 | F23: CAM | G23: =VLOOKUP(F23,$T$3:$U$12,2,0) -> Campeche | I23: SEPTIEMBRE | J23: - | K23: 2022 | L23: CAM | N23: SEPTIEMBRE | O23: 0 | P23: 2022 | Q23: OAX
B24: MAYO | C24: 173826 | D24: 2021 | E24: Cliente 01 | F24: CAM | G24: =VLOOKUP(F24,$T$3:$U$12,2,0) -> Campeche | I24: OCTUBRE | J24: - | K24: 2022 | L24: CAM | N24: OCTUBRE | O24: 0 | P24: 2022 | Q24: OAX
B25: JUNIO | C25: 108750 | D25: 2021 | E25: Cliente 01 | F25: CAM | G25: =VLOOKUP(F25,$T$3:$U$12,2,0) -> Campeche | I25: NOVIEMBRE | J25: - | K25: 2022 | L25: CAM | N25: NOVIEMBRE | O25: 0 | P25: 2022 | Q25: OAX
B26: JULIO | C26: 183454 | D26: 2021 | E26: Cliente 01 | F26: CAM | G26: =VLOOKUP(F26,$T$3:$U$12,2,0) -> Campeche | I26: DICIEMBRE | J26: - | K26: 2022 | L26: CAM | N26: DICIEMBRE | O26: 0 | P26: 2022 | Q26: OAX
B27: AGOSTO | C27: 223242 | D27: 2021 | E27: Cliente 01 | F27: CAM | G27: =VLOOKUP(F27,$T$3:$U$12,2,0) -> Campeche | I27: ENERO | J27: 0.36 | K27: 2022 | L27: ACA | N27: ENERO | O27: 658088.33 | P27: 2021 | Q27: CAM
B28: SEPTIEMBRE | C28: 306008 | D28: 2021 | E28: Cliente 01 | F28: CAM | G28: =VLOOKUP(F28,$T$3:$U$12,2,0) -> Campeche | I28: FEBRERO | J28: 0.38877758 | K28: 2022 | L28: ACA | N28: FEBRERO | O28: 233464.34 | P28: 2021 | Q28: CAM
B29: OCTUBRE | C29: 91872 | D29: 2021 | E29: Cliente 01 | F29: CAM | G29: =VLOOKUP(F29,$T$3:$U$12,2,0) -> Campeche | I29: MARZO | J29: 0.35011666 | K29: 2022 | L29: ACA | N29: MARZO | O29: 115064.51 | P29: 2021 | Q29: CAM
B30: NOVIEMBRE | C30: 47554.2 | D30: 2021 | E30: Cliente 01 | F30: CAM | G30: =VLOOKUP(F30,$T$3:$U$12,2,0) -> Campeche | I30: ABRIL | J30: 0.33977459 | K30: 2022 | L30: ACA | N30: ABRIL | O30: 533999.38 | P30: 2021 | Q30: CAM
B31: DICIEMBRE | C31: 201086.01 | D31: 2021 | E31: Cliente 01 | F31: CAM | G31: =VLOOKUP(F31,$T$3:$U$12,2,0) -> Campeche | I31: MAYO | J31: -0.60957026 | K31: 2022 | L31: ACA | N31: MAYO | O31: -410625.77 | P31: 2021 | Q31: CAM
B32: ENERO | C32: 1020104 | D32: 2022 | E32: Cliente 01 | F32: CAM | G32: =VLOOKUP(F32,$T$3:$U$12,2,0) -> Campeche | I32: JUNIO | J32: - | K32: 2022 | L32: ACA | N32: JUNIO | O32: 346639.4 | P32: 2021 | Q32: CAM
B33: FEBRERO | C33: 308676 | D33: 2022 | E33: Cliente 01 | F33: CAM | G33: =VLOOKUP(F33,$T$3:$U$12,2,0) -> Campeche | I33: JULIO | J33: - | K33: 2022 | L33: ACA | N33: JULIO | O33: 36262.619 | P33: 2021 | Q33: CAM
B34: MARZO | C34: 117566 | D34: 2022 | E34: Cliente 01 | F34: CAM | G34: =VLOOKUP(F34,$T$3:$U$12,2,0) -> Campeche | I34: AGOSTO | J34: - | K34: 2022 | L34: ACA | N34: AGOSTO | O34: 459909.12 | P34: 2021 | Q34: CAM
B35: ABRIL | C35: 66584 | D35: 2022 | E35: Cliente 01 | F35: CAM | G35: =VLOOKUP(F35,$T$3:$U$12,2,0) -> Campeche | I35: SEPTIEMBRE | J35: - | K35: 2022 | L35: ACA | N35: SEPTIEMBRE | O35: 238013 | P35: 2021 | Q35: CAM
B36: MAYO | C36: 55332 | D36: 2022 | E36: Cliente 01 | F36: CAM | G36: =VLOOKUP(F36,$T$3:$U$12,2,0) -> Campeche | I36: OCTUBRE | J36: - | K36: 2022 | L36: ACA | N36: OCTUBRE | O36: 147372.13 | P36: 2021 | Q36: CAM
B37: ENERO | C37: 432448 | D37: 2021 | E37: Cliente 01 | F37: ACA | G37: =VLOOKUP(F37,$T$3:$U$11,2,0) -> Guerrero | I37: NOVIEMBRE | J37: - | K37: 2022 | L37: ACA | N37: NOVIEMBRE | O37: 11984.89 | P37: 2021 | Q37: CAM
B38: FEBRERO | C38: 609580 | D38: 2021 | E38: Cliente 01 | F38: ACA | G38: =VLOOKUP(F38,$T$3:$U$11,2,0) -> Guerrero | I38: DICIEMBRE | J38: - | K38: 2022 | L38: ACA | N38: DICIEMBRE | O38: -448264.56 | P38: 2021 | Q38: CAM
B39: MARZO | C39: 416498 | D39: 2021 | E39: Cliente 01 | F39: ACA | G39: =VLOOKUP(F39,$T$3:$U$11,2,0) -> Guerrero | I39: ENERO | J39: 0.61 | K39: 2022 | L39: MID | N39: ENERO | O39: 2366803.8 | P39: 2022 | Q39: CAM
B40: ABRIL | C40: 473222 | D40: 2021 | E40: Cliente 01 | F40: ACA | G40: =VLOOKUP(F40,$T$3:$U$11,2,0) -> Guerrero | I40: FEBRERO | J40: 0.61948939 | K40: 2022 | L40: MID | N40: FEBRERO | O40: 153849.88 | P40: 2022 | Q40: CAM
...
